0.184900070365
0.462764106298
0.321961062521
[('1', <pro2.Group instance at 0xe1b128>), ('2', <pro2.Group instance at 0xe1b128>), ('2', <pro2.Group instance at 0xe1b290>)]
[('0', <pro2.Group instance at 0xe1b128>), ('1', <pro2.Group instance at 0xe1b2d8>), ('2', <pro2.Group instance at 0xe1b3b0>)]
Traceback (most recent call last):
  File "/home/cs290/cs240_project/python_2/pro.py", line 111, in <module>
    for i in range(len(a.collect())):
  File "/home/cs290/cs240_project/python_2/spark-1.6.0-bin-hadoop2.6/python/lib/pyspark.zip/pyspark/rdd.py", line 771, in collect
  File "/home/cs290/cs240_project/python_2/spark-1.6.0-bin-hadoop2.6/python/lib/py4j-0.9-src.zip/py4j/java_gateway.py", line 813, in __call__
  File "/home/cs290/cs240_project/python_2/spark-1.6.0-bin-hadoop2.6/python/lib/py4j-0.9-src.zip/py4j/protocol.py", line 308, in get_return_value
py4j.protocol.Py4JJavaError: An error occurred while calling z:org.apache.spark.api.python.PythonRDD.collectAndServe.
: org.apache.spark.SparkException: Job aborted due to stage failure: Task 1 in stage 519.0 failed 1 times, most recent failure: Lost task 1.0 in stage 519.0 (TID 266, localhost): org.apache.spark.api.python.PythonException: Traceback (most recent call last):
  File "/home/cs290/cs240_project/python_2/spark-1.6.0-bin-hadoop2.6/python/lib/pyspark.zip/pyspark/worker.py", line 111, in main
    process()
  File "/home/cs290/cs240_project/python_2/spark-1.6.0-bin-hadoop2.6/python/lib/pyspark.zip/pyspark/worker.py", line 106, in process
    serializer.dump_stream(func(split_index, iterator), outfile)
  File "/home/cs290/cs240_project/python_2/spark-1.6.0-bin-hadoop2.6/python/lib/pyspark.zip/pyspark/serializers.py", line 263, in dump_stream
    vs = list(itertools.islice(iterator, batch))
  File "/home/cs290/cs240_project/python_2/par_sim.py", line 24, in similarity
    sc = SparkContext()
  File "/home/cs290/cs240_project/python_2/spark-1.6.0-bin-hadoop2.6/python/lib/pyspark.zip/pyspark/context.py", line 112, in __init__
    SparkContext._ensure_initialized(self, gateway=gateway)
  File "/home/cs290/cs240_project/python_2/spark-1.6.0-bin-hadoop2.6/python/lib/pyspark.zip/pyspark/context.py", line 261, in _ensure_initialized
    callsite.function, callsite.file, callsite.linenum))
ValueError: Cannot run multiple SparkContexts at once; existing SparkContext(app=pyspark-shell, master=local[*]) created by <module> at /usr/lib64/python2.7/runpy.py:72 

	at org.apache.spark.api.python.PythonRunner$$anon$1.read(PythonRDD.scala:166)
	at org.apache.spark.api.python.PythonRunner$$anon$1.<init>(PythonRDD.scala:207)
	at org.apache.spark.api.python.PythonRunner.compute(PythonRDD.scala:125)
	at org.apache.spark.api.python.PythonRDD.compute(PythonRDD.scala:70)
	at org.apache.spark.rdd.RDD.computeOrReadCheckpoint(RDD.scala:306)
	at org.apache.spark.rdd.RDD.iterator(RDD.scala:270)
	at org.apache.spark.scheduler.ResultTask.runTask(ResultTask.scala:66)
	at org.apache.spark.scheduler.Task.run(Task.scala:89)
	at org.apache.spark.executor.Executor$TaskRunner.run(Executor.scala:213)
	at java.util.concurrent.ThreadPoolExecutor.runWorker(ThreadPoolExecutor.java:1142)
	at java.util.concurrent.ThreadPoolExecutor$Worker.run(ThreadPoolExecutor.java:617)
	at java.lang.Thread.run(Thread.java:745)

Driver stacktrace:
	at org.apache.spark.scheduler.DAGScheduler.org$apache$spark$scheduler$DAGScheduler$$failJobAndIndependentStages(DAGScheduler.scala:1431)
	at org.apache.spark.scheduler.DAGScheduler$$anonfun$abortStage$1.apply(DAGScheduler.scala:1419)
	at org.apache.spark.scheduler.DAGScheduler$$anonfun$abortStage$1.apply(DAGScheduler.scala:1418)
	at scala.collection.mutable.ResizableArray$class.foreach(ResizableArray.scala:59)
	at scala.collection.mutable.ArrayBuffer.foreach(ArrayBuffer.scala:47)
	at org.apache.spark.scheduler.DAGScheduler.abortStage(DAGScheduler.scala:1418)
	at org.apache.spark.scheduler.DAGScheduler$$anonfun$handleTaskSetFailed$1.apply(DAGScheduler.scala:799)
	at org.apache.spark.scheduler.DAGScheduler$$anonfun$handleTaskSetFailed$1.apply(DAGScheduler.scala:799)
	at scala.Option.foreach(Option.scala:236)
	at org.apache.spark.scheduler.DAGScheduler.handleTaskSetFailed(DAGScheduler.scala:799)
	at org.apache.spark.scheduler.DAGSchedulerEventProcessLoop.doOnReceive(DAGScheduler.scala:1640)
	at org.apache.spark.scheduler.DAGSchedulerEventProcessLoop.onReceive(DAGScheduler.scala:1599)
	at org.apache.spark.scheduler.DAGSchedulerEventProcessLoop.onReceive(DAGScheduler.scala:1588)
	at org.apache.spark.util.EventLoop$$anon$1.run(EventLoop.scala:48)
	at org.apache.spark.scheduler.DAGScheduler.runJob(DAGScheduler.scala:620)
	at org.apache.spark.SparkContext.runJob(SparkContext.scala:1832)
	at org.apache.spark.SparkContext.runJob(SparkContext.scala:1845)
	at org.apache.spark.SparkContext.runJob(SparkContext.scala:1858)
	at org.apache.spark.SparkContext.runJob(SparkContext.scala:1929)
	at org.apache.spark.rdd.RDD$$anonfun$collect$1.apply(RDD.scala:927)
	at org.apache.spark.rdd.RDDOperationScope$.withScope(RDDOperationScope.scala:150)
	at org.apache.spark.rdd.RDDOperationScope$.withScope(RDDOperationScope.scala:111)
	at org.apache.spark.rdd.RDD.withScope(RDD.scala:316)
	at org.apache.spark.rdd.RDD.collect(RDD.scala:926)
	at org.apache.spark.api.python.PythonRDD$.collectAndServe(PythonRDD.scala:405)
	at org.apache.spark.api.python.PythonRDD.collectAndServe(PythonRDD.scala)
	at sun.reflect.GeneratedMethodAccessor22.invoke(Unknown Source)
	at sun.reflect.DelegatingMethodAccessorImpl.invoke(DelegatingMethodAccessorImpl.java:43)
	at java.lang.reflect.Method.invoke(Method.java:497)
	at py4j.reflection.MethodInvoker.invoke(MethodInvoker.java:231)
	at py4j.reflection.ReflectionEngine.invoke(ReflectionEngine.java:381)
	at py4j.Gateway.invoke(Gateway.java:259)
	at py4j.commands.AbstractCommand.invokeMethod(AbstractCommand.java:133)
	at py4j.commands.CallCommand.execute(CallCommand.java:79)
	at py4j.GatewayConnection.run(GatewayConnection.java:209)
	at java.lang.Thread.run(Thread.java:745)
Caused by: org.apache.spark.api.python.PythonException: Traceback (most recent call last):
  File "/home/cs290/cs240_project/python_2/spark-1.6.0-bin-hadoop2.6/python/lib/pyspark.zip/pyspark/worker.py", line 111, in main
    process()
  File "/home/cs290/cs240_project/python_2/spark-1.6.0-bin-hadoop2.6/python/lib/pyspark.zip/pyspark/worker.py", line 106, in process
    serializer.dump_stream(func(split_index, iterator), outfile)
  File "/home/cs290/cs240_project/python_2/spark-1.6.0-bin-hadoop2.6/python/lib/pyspark.zip/pyspark/serializers.py", line 263, in dump_stream
    vs = list(itertools.islice(iterator, batch))
  File "/home/cs290/cs240_project/python_2/par_sim.py", line 24, in similarity
    sc = SparkContext()
  File "/home/cs290/cs240_project/python_2/spark-1.6.0-bin-hadoop2.6/python/lib/pyspark.zip/pyspark/context.py", line 112, in __init__
    SparkContext._ensure_initialized(self, gateway=gateway)
  File "/home/cs290/cs240_project/python_2/spark-1.6.0-bin-hadoop2.6/python/lib/pyspark.zip/pyspark/context.py", line 261, in _ensure_initialized
    callsite.function, callsite.file, callsite.linenum))
ValueError: Cannot run multiple SparkContexts at once; existing SparkContext(app=pyspark-shell, master=local[*]) created by <module> at /usr/lib64/python2.7/runpy.py:72 

	at org.apache.spark.api.python.PythonRunner$$anon$1.read(PythonRDD.scala:166)
	at org.apache.spark.api.python.PythonRunner$$anon$1.<init>(PythonRDD.scala:207)
	at org.apache.spark.api.python.PythonRunner.compute(PythonRDD.scala:125)
	at org.apache.spark.api.python.PythonRDD.compute(PythonRDD.scala:70)
	at org.apache.spark.rdd.RDD.computeOrReadCheckpoint(RDD.scala:306)
	at org.apache.spark.rdd.RDD.iterator(RDD.scala:270)
	at org.apache.spark.scheduler.ResultTask.runTask(ResultTask.scala:66)
	at org.apache.spark.scheduler.Task.run(Task.scala:89)
	at org.apache.spark.executor.Executor$TaskRunner.run(Executor.scala:213)
	at java.util.concurrent.ThreadPoolExecutor.runWorker(ThreadPoolExecutor.java:1142)
	at java.util.concurrent.ThreadPoolExecutor$Worker.run(ThreadPoolExecutor.java:617)
	... 1 more

